Workbook

Sheet Leia_me
A1: Validação do cálculo do UFSCar Cloud Selector
A3: Como usar
A4: 1 | B4: As abas seguem a ordem do cálculo: Parametros → AHP_Dimensoes → Pesos_Indicadores → Normalizacao → Pesos_Efetivos → Pontuacao → Sensibilidade → Conferencia.
A5: 2 | B5: Altere só células amarelas (texto azul). Todo o resto é fórmula.
A6: 3 | B6: Conferencia compara a planilha com o relatório publicado. Ao simular, ela passa a acusar DIVERGE: é o esperado.
A8: Cores | D8: Destaques: valores que aparecem no relatório
A9: Amarelo, texto azul | B9: Entrada | D9: Azul | E9: Peso exibido no relatório: matriz e pesos do AHP ("Autovetor principal → pesos"), peso efetivo por dimensão e por indicador
A10: Texto preto | B10: Fórmula da própria aba | D10: Laranja | E10: Nota normalizada e parcela (peso × nota): "Peso × nota em cada dimensão" e "O que separou os provedores"
A11: Texto verde | B11: Fórmula que puxa de outra aba | D11: Lilás | E11: Qualidade do resultado: λmax, IC, RC, conjunto V, taxa de comparabilidade, margem, empate e sensibilidade
A12: Verde claro | B12: Verificação (OK / DIVERGE) | D12: Verde | E12: Resultado final: pontuação de cada provedor e ranking ("Pontuação final", "Posição e empate")
A14: Equações
A15: AHP | B15: a_ji = 1/a_ij · N_ij = A_ij ÷ Σ_i A_ij · W_d = média da linha · CR = ((λmax − n)/(n − 1)) ÷ RI
A16: Pesos | B16: l_j = v_j ÷ Σ v da dimensão · w_j = W_d × l_j
A17: Safra | B17: Se os anos das evidências FOUND de um indicador distam mais que a tolerância, o indicador vira INVALID para todos.
A18: Normalização | B18: benefício r = x ÷ máx · minimização r = mín ÷ x · qualitativo r = valor da rubrica (sem divisão) · máx e mín só dos valores observados; zero imputado em vermelho na Normalizacao
A19: Conjunto V | B19: Entra quem tem valor para ao menos um provedor e fórmula definida entre os observados; o provedor sem valor recebe r = 0 como penalidade (Parametros B50; NÃO volta à regra 'valor para os três'). Sai também o indicador que dá a mesma nota a todos, salvo se nenhum separar.
A20: Pesos efetivos | B20: w'_j = w_j ÷ Σ_{k∈V} w_k
A21: Equação 5 | B21: S_i = Σ_{j∈V} w'_j × r_ij · empate quando a diferença para o líder do grupo ≤ margem
A22: Sensibilidade | B22: W_d em [0,1], demais reescaladas na proporção; menor Δ que troca o líder
A24: Caso carregado
A25: Submissão | B25: ce0f9d95e77a4017af6056baa0009556 · simulação com foco em Segurança da Informação · backend/data/audit.db · reenvio de 29/09/2026 (envio original de 23/09: 04ef7f39…, números na coluna G da Conferencia)
A26: Hashes | B26: indicadores 84aacdd97b2e… · escalas d99dde2a8459… (zero para evidência parcial; indicador de nota igual mantido na soma)
A27: Resultado | B27: Microsoft Azure 0,822668 · Google Cloud 0,769966 · AWS 0,746160

Sheet Parametros
A1: Parâmetros metodológicos
A2: Espelha backend/methodology/scales.json. Células amarelas são decisões da dissertação.
A4: Escala de Saaty
A5: Intensidade | B5: Valor
A6: moderada | B6: 3
A7: forte | B7: 5
A8: muito forte | B8: 7
A9: extrema | B9: 9
A11: Índice randômico de Saaty (RI)
A12: n | B12: RI
A13: 1 | B13: 0
A14: 2 | B14: 0
A15: 3 | B15: 0.58
A16: 4 | B16: 0.9
A17: 5 | B17: 1.12
A18: 6 | B18: 1.24
A19: 7 | B19: 1.32
A20: 8 | B20: 1.41
A21: 9 | B21: 1.45
A22: 10 | B22: 1.49
A24: Coeficientes de relevância (blocos A, B e C)
A25: Resposta | B25: v
A26: Decisivo (critério indispensável) | B26: 5
A27: Muito relevante | B27: 4
A28: Relevante | B28: 3
A29: Pouco relevante | B29: 2
A30: Irrelevante | B30: 1
A31: Não sei / não tenho informações suficientes | B31: nulo | C31: Nulo não é zero: o indicador fica sem peso e sai do cálculo.
A33: Rubrica qualitativa (Quadro 23)
A34: Nível | B34: Valor
A35: nao_identificado | B35: — | C35: '—' não é zero: se nenhum provedor tiver valor, o indicador sai da comparação. Se só parte tiver, o ausente recebe 0 como penalidade (Parametros B50).
A36: baixo | B36: 0.25
A37: moderado | B37: 0.5
A38: alto | B38: 0.75
A39: completo | B39: 1
A41: Regras de decisão
A42: Parâmetro | B42: Valor | C42: Chave no scales.json / código
A43: Limite de consistência (CR máximo) | B43: 0.1 | C43: ahp.consistency_threshold
A44: Margem de indiferença (empate) | B44: 0.02 | C44: tie_break.tolerance
A45: Excluir indicador que dá a mesma nota a todos | B45: NÃO | C45: comparability.exclude_non_discriminative
...

Sheet AHP_Dimensoes
A1: Etapa 1 — Pesos das dimensões (AHP, bloco D) · Simulação: Foco em Segurança da Informação
A2: backend/app/pairwise.py + ahp.py · a_ij = intensidade se a preferida é i; 1/intensidade se é j; 1 se igual · W_d = média da linha da matriz normalizada.
A4: 1.1 Julgamentos (entrada)
A5: Dimensão A | B5: Dimensão B | C5: Preferência (A, B ou Igual) | D5: Intensidade | E5: Valor de Saaty | F5: a_AB
A6: Sustentabilidade | B6: Desempenho Operacional | C6: Igual | E6: =IF(C6="Igual",1,IFERROR(VLOOKUP(D6,Parametros!$A$6:$B$9,2,FALSE()),"")) -> 1 | F6: =IF(C6="Igual",1,IF(C6="A",E6,1/E6)) -> 1
A7: Sustentabilidade | B7: Segurança da Informação | C7: B | D7: extrema | E7: =IF(C7="Igual",1,IFERROR(VLOOKUP(D7,Parametros!$A$6:$B$9,2,FALSE()),"")) -> 9 | F7: =IF(C7="Igual",1,IF(C7="A",E7,1/E7)) -> 0.11111111
A8: Desempenho Operacional | B8: Segurança da Informação | C8: B | D8: extrema | E8: =IF(C8="Igual",1,IFERROR(VLOOKUP(D8,Parametros!$A$6:$B$9,2,FALSE()),"")) -> 9 | F8: =IF(C8="Igual",1,IF(C8="A",E8,1/E8)) -> 0.11111111
A9: A = a dimensão da coluna A é a preferida; B = a da coluna B; Igual = indiferença (intensidade vazia).
A11: 1.2 Matriz de comparação A (a_ji = 1/a_ij)
B12: Sustentabilidade | C12: Desempenho Operacional | D12: Segurança da Informação
A13: Sustentabilidade | B13: =1 -> 1 | C13: =F6 -> 1 | D13: =F7 -> 0.11111111
A14: Desempenho Operacional | B14: =1/C13 -> 1 | C14: =1 -> 1 | D14: =F8 -> 0.11111111
A15: Segurança da Informação | B15: =1/D13 -> 9 | C15: =1/D14 -> 9 | D15: =1 -> 1
A16: Σ da coluna | B16: =SUM(B13:B15) -> 11 | C16: =SUM(C13:C15) -> 11 | D16: =SUM(D13:D15) -> 1.2222222
A18: 1.3 Matriz normalizada N_ij = A_ij ÷ Σ coluna e peso W_d
B19: Sustentabilidade | C19: Desempenho Operacional | D19: Segurança da Informação | E19: W_d | F19: %
A20: Sustentabilidade | B20: =B13/B$16 -> 0.090909091 | C20: =C13/C$16 -> 0.090909091 | D20: =D13/D$16 -> 0.090909091 | E20: =AVERAGE(B20:D20) -> 0.090909091 | F20: =E20 -> 0.090909091
A21: Desempenho Operacional | B21: =B14/B$16 -> 0.090909091 | C21: =C14/C$16 -> 0.090909091 | D21: =D14/D$16 -> 0.090909091 | E21: =AVERAGE(B21:D21) -> 0.090909091 | F21: =E21 -> 0.090909091
A22: Segurança da Informação | B22: =B15/B$16 -> 0.81818182 | C22: =C15/C$16 -> 0.81818182 | D22: =D15/D$16 -> 0.81818182 | E22: =AVERAGE(B22:D22) -> 0.81818182 | F22: =E22 -> 0.81818182
A23: Σ | E23: =SUM(E20:E22) -> 1 | F23: =IF(ABS(E23-1)<0.000001,"OK","DIVERGE") -> OK
A25: 1.4 Consistência
A26: Dimensão | B26: (A·W)_i | C26: (A·W)_i ÷ W_i
A27: Sustentabilidade | B27: =B13*$E$20+C13*$E$21+D13*$E$22 -> 0.27272727 | C27: =B27/E20 -> 3
A28: Desempenho Operacional | B28: =B14*$E$20+C14*$E$21+D14*$E$22 -> 0.27272727 | C28: =B28/E21 -> 3
A29: Segurança da Informação | B29: =B15*$E$20+C15*$E$21+D15*$E$22 -> 2.4545455 | C29: =B29/E22 -> 3
A30: λmax = média de (A·W)_i ÷ W_i | B30: =AVERAGE(C27:C29) -> 3
A31: n | B31: =COUNT(B13:B15) -> 3
A32: CI = (λmax − n) ÷ (n − 1) | B32: =(B30-B31)/(B31-1) -> 0
A33: RI | B33: =VLOOKUP(B31,Parametros!$A$13:$B$22,2,FALSE()) -> 0.58
A34: CR = CI ÷ RI | B34: =IF(B33=0,0,B32/B33) -> 0
A35: Limite | B35: =Parametros!$B$43 -> 0.1
A36: Julgamento | B36: =IF(B34<=B35,"CONSISTENTE","INCONSISTENTE") -> CONSISTENTE

Sheet Pesos_Indicadores
A1: Etapa 2 — Pesos local e global dos indicadores (blocos A, B e C)
A2: backend/app/domain/weights.py · l_j = v_j ÷ Σ v da dimensão · w_j = W_d × l_j · 'Não sei' dá coeficiente nulo: o indicador fica sem peso.
A4: Indicador | B4: Dimensão | C4: Relevância (entrada) | D4: v_j | E4: Σ v na dimensão | F4: Peso local l_j | G4: Peso da dimensão W_d | H4: Peso global w_j | I4: l_j (0 se nulo, auxiliar)
A5: Eficiência energética dos data centers (PUE) | B5: Sustentabilidade | C5: Relevante | D5: =IF(C5="","",IFERROR(VLOOKUP(C5,Parametros!$A$26:$B$31,2,FALSE()),"?")) -> 3 | E5: =SUMIF($B$5:$B$17,B5,$D$5:$D$17) -> 16 | F5: =IF(AND(ISNUMBER(D5),E5>0),D5/E5,"") -> 0.1875 | G5: =VLOOKUP(B5,AHP_Dimensoes!$A$20:$E$22,5,FALSE()) -> 0.090909091 | H5: =IF(F5="","",G5*F5) -> 0.017045455 | I5: =IF(ISNUMBER(F5),F5,0) -> 0.1875
A6: Utilização de fontes de energia renovável (%) | B6: Sustentabilidade | C6: Muito relevante | D6: =IF(C6="","",IFERROR(VLOOKUP(C6,Parametros!$A$26:$B$31,2,FALSE()),"?")) -> 4 | E6: =SUMIF($B$5:$B$17,B6,$D$5:$D$17) -> 16 | F6: =IF(AND(ISNUMBER(D6),E6>0),D6/E6,"") -> 0.25 | G6: =VLOOKUP(B6,AHP_Dimensoes!$A$20:$E$22,5,FALSE()) -> 0.090909091 | H6: =IF(F6="","",G6*F6) -> 0.022727273 | I6: =IF(ISNUMBER(F6),F6,0) -> 0.25
A7: Redução de emissões de gases de efeito estufa | B7: Sustentabilidade | C7: Relevante | D7: =IF(C7="","",IFERROR(VLOOKUP(C7,Parametros!$A$26:$B$31,2,FALSE()),"?")) -> 3 | E7: =SUMIF($B$5:$B$17,B7,$D$5:$D$17) -> 16 | F7: =IF(AND(ISNUMBER(D7),E7>0),D7/E7,"") -> 0.1875 | G7: =VLOOKUP(B7,AHP_Dimensoes!$A$20:$E$22,5,FALSE()) -> 0.090909091 | H7: =IF(F7="","",G7*F7) -> 0.017045455 | I7: =IF(ISNUMBER(F7),F7,0) -> 0.1875
A8: Gestão de resíduos eletrônicos (% de desvio de aterro) | B8: Sustentabilidade | C8: Relevante | D8: =IF(C8="","",IFERROR(VLOOKUP(C8,Parametros!$A$26:$B$31,2,FALSE()),"?")) -> 3 | E8: =SUMIF($B$5:$B$17,B8,$D$5:$D$17) -> 16 | F8: =IF(AND(ISNUMBER(D8),E8>0),D8/E8,"") -> 0.1875 | G8: =VLOOKUP(B8,AHP_Dimensoes!$A$20:$E$22,5,FALSE()) -> 0.090909091 | H8: =IF(F8="","",G8*F8) -> 0.017045455 | I8: =IF(ISNUMBER(F8),F8,0) -> 0.1875
A9: Circularidade e ciclo de vida dos equipamentos | B9: Sustentabilidade | C9: Relevante | D9: =IF(C9="","",IFERROR(VLOOKUP(C9,Parametros!$A$26:$B$31,2,FALSE()),"?")) -> 3 | E9: =SUMIF($B$5:$B$17,B9,$D$5:$D$17) -> 16 | F9: =IF(AND(ISNUMBER(D9),E9>0),D9/E9,"") -> 0.1875 | G9: =VLOOKUP(B9,AHP_Dimensoes!$A$20:$E$22,5,FALSE()) -> 0.090909091 | H9: =IF(F9="","",G9*F9) -> 0.017045455 | I9: =IF(ISNUMBER(F9),F9,0) -> 0.1875
A10: Disponibilidade dos serviços (%) | B10: Desempenho Operacional | C10: Muito relevante | D10: =IF(C10="","",IFERROR(VLOOKUP(C10,Parametros!$A$26:$B$31,2,FALSE()),"?")) -> 4 | E10: =SUMIF($B$5:$B$17,B10,$D$5:$D$17) -> 13 | F10: =IF(AND(ISNUMBER(D10),E10>0),D10/E10,"") -> 0.30769231 | G10: =VLOOKUP(B10,AHP_Dimensoes!$A$20:$E$22,5,FALSE()) -> 0.090909091 | H10: =IF(F10="","",G10*F10) -> 0.027972028 | I10: =IF(ISNUMBER(F10),F10,0) -> 0.30769231
A11: Suporte técnico e resposta a incidentes | B11: Desempenho Operacional | C11: Relevante | D11: =IF(C11="","",IFERROR(VLOOKUP(C11,Parametros!$A$26:$B$31,2,FALSE()),"?")) -> 3 | E11: =SUMIF($B$5:$B$17,B11,$D$5:$D$17) -> 13 | F11: =IF(AND(ISNUMBER(D11),E11>0),D11/E11,"") -> 0.23076923 | G11: =VLOOKUP(B11,AHP_Dimensoes!$A$20:$E$22,5,FALSE()) -> 0.090909091 | H11: =IF(F11="","",G11*F11) -> 0.020979021 | I11: =IF(ISNUMBER(F11),F11,0) -> 0.23076923
A12: Latência e tempo de resposta (ms) | B12: Desempenho Operacional | C12: Relevante | D12: =IF(C12="","",IFERROR(VLOOKUP(C12,Parametros!$A$26:$B$31,2,FALSE()),"?")) -> 3 | E12: =SUMIF($B$5:$B$17,B12,$D$5:$D$17) -> 13 | F12: =IF(AND(ISNUMBER(D12),E12>0),D12/E12,"") -> 0.23076923 | G12: =VLOOKUP(B12,AHP_Dimensoes!$A$20:$E$22,5,FALSE()) -> 0.090909091 | H12: =IF(F12="","",G12*F12) -> 0.020979021 | I12: =IF(ISNUMBER(F12),F12,0) -> 0.23076923
A13: Escalabilidade e elasticidade | B13: Desempenho Operacional | C13: Relevante | D13: =IF(C13="","",IFERROR(VLOOKUP(C13,Parametros!$A$26:$B$31,2,FALSE()),"?")) -> 3 | E13: =SUMIF($B$5:$B$17,B13,$D$5:$D$17) -> 13 | F13: =IF(AND(ISNUMBER(D13),E13>0),D13/E13,"") -> 0.23076923 | G13: =VLOOKUP(B13,AHP_Dimensoes!$A$20:$E$22,5,FALSE()) -> 0.090909091 | H13: =IF(F13="","",G13*F13) -> 0.020979021 | I13: =IF(ISNUMBER(F13),F13,0) -> 0.23076923
A14: Certificações e conformidade | B14: Segurança da Informação | C14: Decisivo (critério indispensável) | D14: =IF(C14="","",IFERROR(VLOOKUP(C14,Parametros!$A$26:$B$31,2,FALSE()),"?")) -> 5 | E14: =SUMIF($B$5:$B$17,B14,$D$5:$D$17) -> 20 | F14: =IF(AND(ISNUMBER(D14),E14>0),D14/E14,"") -> 0.25 | G14: =VLOOKUP(B14,AHP_Dimensoes!$A$20:$E$22,5,FALSE()) -> 0.81818182 | H14: =IF(F14="","",G14*F14) -> 0.20454545 | I14: =IF(ISNUMBER(F14),F14,0) -> 0.25
A15: Backup, recuperação de desastres e continuidade | B15: Segurança da Informação | C15: Decisivo (critério indispensável) | D15: =IF(C15="","",IFERROR(VLOOKUP(C15,Parametros!$A$26:$B$31,2,FALSE()),"?")) -> 5 | E15: =SUMIF($B$5:$B$17,B15,$D$5:$D$17) -> 20 | F15: =IF(AND(ISNUMBER(D15),E15>0),D15/E15,"") -> 0.25 | G15: =VLOOKUP(B15,AHP_Dimensoes!$A$20:$E$22,5,FALSE()) -> 0.81818182 | H15: =IF(F15="","",G15*F15) -> 0.20454545 | I15: =IF(ISNUMBER(F15),F15,0) -> 0.25
A16: Identidade, autenticação e controle de acesso | B16: Segurança da Informação | C16: Decisivo (critério indispensável) | D16: =IF(C16="","",IFERROR(VLOOKUP(C16,Parametros!$A$26:$B$31,2,FALSE()),"?")) -> 5 | E16: =SUMIF($B$5:$B$17,B16,$D$5:$D$17) -> 20 | F16: =IF(AND(ISNUMBER(D16),E16>0),D16/E16,"") -> 0.25 | G16: =VLOOKUP(B16,AHP_Dimensoes!$A$20:$E$22,5,FALSE()) -> 0.81818182 | H16: =IF(F16="","",G16*F16) -> 0.20454545 | I16: =IF(ISNUMBER(F16),F16,0) -> 0.25
A17: Proteção de dados e criptografia | B17: Segurança da Informação | C17: Decisivo (critério indispensável) | D17: =IF(C17="","",IFERROR(VLOOKUP(C17,Parametros!$A$26:$B$31,2,FALSE()),"?")) -> 5 | E17: =SUMIF($B$5:$B$17,B17,$D$5:$D$17) -> 20 | F17: =IF(AND(ISNUMBER(D17),E17>0),D17/E17,"") -> 0.25 | G17: =VLOOKUP(B17,AHP_Dimensoes!$A$20:$E$22,5,FALSE()) -> 0.81818182 | H17: =IF(F17="","",G17*F17) -> 0.20454545 | I17: =IF(ISNUMBER(F17),F17,0) -> 0.25
A19: Verificações
A20: Dimensão | B20: Σ l_j (deve ser 1) | C20: Σ w_j | D20: W_d | E20: Situação
A21: Sustentabilidade | B21: =SUMIF($B$5:$B$17,A21,$F$5:$F$17) -> 1 | C21: =SUMIF($B$5:$B$17,A21,$H$5:$H$17) -> 0.090909091 | D21: =VLOOKUP(A21,AHP_Dimensoes!$A$20:$E$22,5,FALSE()) -> 0.090909091 | E21: =IF(SUMIF($B$5:$B$17,A21,$D$5:$D$17)=0,"REVISAR — nenhum coeficiente válido",IF(AND(ABS(B21-1)<0.000001,ABS(C21-D21)<0.000001),"OK","DIVERGE")) -> OK
A22: Desempenho Operacional | B22: =SUMIF($B$5:$B$17,A22,$F$5:$F$17) -> 1 | C22: =SUMIF($B$5:$B$17,A22,$H$5:$H$17) -> 0.090909091 | D22: =VLOOKUP(A22,AHP_Dimensoes!$A$20:$E$22,5,FALSE()) -> 0.090909091 | E22: =IF(SUMIF($B$5:$B$17,A22,$D$5:$D$17)=0,"REVISAR — nenhum coeficiente válido",IF(AND(ABS(B22-1)<0.000001,ABS(C22-D22)<0.000001),"OK","DIVERGE")) -> OK
A23: Segurança da Informação | B23: =SUMIF($B$5:$B$17,A23,$F$5:$F$17) -> 1 | C23: =SUMIF($B$5:$B$17,A23,$H$5:$H$17) -> 0.81818182 | D23: =VLOOKUP(A23,AHP_Dimensoes!$A$20:$E$22,5,FALSE()) -> 0.81818182 | E23: =IF(SUMIF($B$5:$B$17,A23,$D$5:$D$17)=0,"REVISAR — nenhum coeficiente válido",IF(AND(ABS(B23-1)<0.000001,ABS(C23-D23)<0.000001),"OK","DIVERGE")) -> OK
A24: Σ w_j de todos os indicadores | C24: =SUM($H$5:$H$17) -> 1 | E24: =IF(ABS(C24-1)<0.000001,"OK","DIVERGE") -> OK

Sheet Normalizacao
A1: Etapa 3 — Da evidência ao valor comparável e ao conjunto V
A2: backend/app/evidence.py (safra) + domain/normalization.py · benefício r = x ÷ máx · minimização r = mín ÷ x · qualitativo r = valor da rubrica · ausência total não vira zero; evidência parcial dá r = 0 ao ausente (penalidade, Parametros B50), com máx/mín só dos observados.
F3: AWS (entrada) | I3: Google Cloud (entrada) | L3: Microsoft Azure (entrada)
A4: Indicador | B4: Dimensão | C4: Tipo | D4: Direção | E4: Peso global w_j | F4: Status | G4: Valor ou categoria | H4: Ano | I4: Status | J4: Valor ou categoria | K4: Ano | L4: Status | M4: Valor ou categoria | N4: Ano | O4: Ano FOUND AWS | P4: Ano FOUND Google | Q4: Ano FOUND Azure | R4: Safras distantes? | S4: Status efetivo AWS | T4: Status efetivo Google | U4: Status efetivo Azure | V4: x AWS | W4: x Google | X4: x Azure | Y4: Nº com x | Z4: mín x | AA4: máx x | AB4: Motivo (normalização) | AC4: r AWS | AD4: r Google | AE4: r Azure | AF4: Mesma nota para todos? | AG4: Motivo final da exclusão | AH4: Entra na Eq. 5? | AI4: r aux AWS | AJ4: r aux Google | AK4: r aux Azure | AL4: V aux | AM4: Zero imputado (penalidade)
A5: Eficiência energética dos data centers (PUE) | B5: Sustentabilidade | C5: quantitativo | D5: minimização | E5: =Pesos_Indicadores!H5 -> 0.017045455 | F5: FOUND | G5: 1.14 | H5: 2026 | I5: FOUND | J5: 1.09 | K5: 2026 | L5: FOUND | M5: 1.17 | N5: 2026 | O5: =IF(AND(F5="FOUND",ISNUMBER(H5)),H5,"") -> 2026 | P5: =IF(AND(I5="FOUND",ISNUMBER(K5)),K5,"") -> 2026 | Q5: =IF(AND(L5="FOUND",ISNUMBER(N5)),N5,"") -> 2026 | R5: =IF(OR(Parametros!$B$46="",COUNT(O5:Q5)<2),"não",IF(MAX(O5:Q5)-MIN(O5:Q5)>Parametros!$B$46,"sim","não")) -> não | S5: =IF(AND($R5="sim",OR(F5="FOUND",F5="PARTIAL")),"INVALID",IF(F5<>"FOUND",F5,IF($C5="qualitativo",IF(G5="","NOT_FOUND",IF(ISNA(MATCH(G5,Parametros!$A$35:$A$39,0)),"INVALID",IF(ISNUMBER(VLOOKUP(G5,Parametros!$A$35:$B$39,2,FALSE())),"FOUND","NOT_FOUND"))),IF(ISNUMBER(G5),"FOUND","NOT_FOUND")))) -> FOUND | T5: =IF(AND($R5="sim",OR(I5="FOUND",I5="PARTIAL")),"INVALID",IF(I5<>"FOUND",I5,IF($C5="qualitativo",IF(J5="","NOT_FOUND",IF(ISNA(MATCH(J5,Parametros!$A$35:$A$39,0)),"INVALID",IF(ISNUMBER(VLOOKUP(J5,Parametros!$A$35:$B$39,2,FALSE())),"FOUND","NOT_FOUND"))),IF(ISNUMBER(J5),"FOUND","NOT_FOUND")))) -> FOUND | U5: =IF(AND($R5="sim",OR(L5="FOUND",L5="PARTIAL")),"INVALID",IF(L5<>"FOUND",L5,IF($C5="qualitativo",IF(M5="","NOT_FOUND",IF(ISNA(MATCH(M5,Parametros!$A$35:$A$39,0)),"INVALID",IF(ISNUMBER(VLOOKUP(M5,Parametros!$A$35:$B$39,2,FALSE())),"FOUND","NOT_FOUND"))),IF(ISNUMBER(M5),"FOUND","NOT_FOUND")))) -> FOUND | V5: =IF(S5<>"FOUND","",IF($C5="qualitativo",VLOOKUP(G5,Parametros!$A$35:$B$39,2,FALSE()),G5)) -> 1.14 | W5: =IF(T5<>"FOUND","",IF($C5="qualitativo",VLOOKUP(J5,Parametros!$A$35:$B$39,2,FALSE()),J5)) -> 1.09 | X5: =IF(U5<>"FOUND","",IF($C5="qualitativo",VLOOKUP(M5,Parametros!$A$35:$B$39,2,FALSE()),M5)) -> 1.17 | Y5: =COUNT(V5:X5) -> 3 | Z5: =IF(Y5=0,"",MIN(V5:X5)) -> 1.09 | AA5: =IF(Y5=0,"",MAX(V5:X5)) -> 1.17 | AB5: =IF(NOT(ISNUMBER(E5)),"no_weight",IF(Y5=0,IF(AND(S5="INVALID",T5="INVALID",U5="INVALID"),"invalid_for_comparison","no_evidence"),IF(AND(Y5<3,Parametros!$B$50<>"SIM"),"missing_for_some_providers",IF(C5="qualitativo",IF(OR(Z5<0,AA5>1),"invalid_for_comparison",""),IF(D5="benefício",IF(AA5=0,"non_discriminative",IF(AA5<0,"invalid_for_comparison","")),IF(Z5<=0,"invalid_for_comparison","")))))) | AC5: =IF(AB5<>"","",IF(V5="",0,IF(C5="qualitativo",V5,IF(D5="minimização",Z5/V5,V5/AA5)))) -> 0.95614035 | AD5: =IF(AB5<>"","",IF(W5="",0,IF(C5="qualitativo",W5,IF(D5="minimização",Z5/W5,W5/AA5)))) -> 1 | AE5: =IF(AB5<>"","",IF(X5="",0,IF(C5="qualitativo",X5,IF(D5="minimização",Z5/X5,X5/AA5)))) -> 0.93162393 | AF5: =IF(AB5<>"","",IF(MAX(AC5:AE5)-MIN(AC5:AE5)<=Parametros!$B$47,"sim","não")) -> não | AG5: =IF(AB5<>"",AB5,IF(AND(AF5="sim",$B$23="sim"),"non_discriminative","")) | AH5: =IF(AG5="","sim","não") -> sim | AI5: =IF(ISNUMBER(AC5),AC5,0) -> 0.95614035 | AJ5: =IF(ISNUMBER(AD5),AD5,0) -> 1 | AK5: =IF(ISNUMBER(AE5),AE5,0) -> 0.93162393 | AL5: =IF(AH5="sim",1,0) -> 1 | AM5: =IF(AND(AH5="sim",Y5<3),TRIM(IF(V5="","AWS ","")&IF(W5="","Google ","")&IF(X5="","Azure","")),"")
A6: Utilização de fontes de energia renovável (%) | B6: Sustentabilidade | C6: quantitativo | D6: benefício | E6: =Pesos_Indicadores!H6 -> 0.022727273 | F6: INVALID | I6: FOUND | J6: 96 | K6: 2026 | L6: FOUND | M6: 100 | N6: 2026 | O6: =IF(AND(F6="FOUND",ISNUMBER(H6)),H6,"") | P6: =IF(AND(I6="FOUND",ISNUMBER(K6)),K6,"") -> 2026 | Q6: =IF(AND(L6="FOUND",ISNUMBER(N6)),N6,"") -> 2026 | R6: =IF(OR(Parametros!$B$46="",COUNT(O6:Q6)<2),"não",IF(MAX(O6:Q6)-MIN(O6:Q6)>Parametros!$B$46,"sim","não")) -> não | S6: =IF(AND($R6="sim",OR(F6="FOUND",F6="PARTIAL")),"INVALID",IF(F6<>"FOUND",F6,IF($C6="qualitativo",IF(G6="","NOT_FOUND",IF(ISNA(MATCH(G6,Parametros!$A$35:$A$39,0)),"INVALID",IF(ISNUMBER(VLOOKUP(G6,Parametros!$A$35:$B$39,2,FALSE())),"FOUND","NOT_FOUND"))),IF(ISNUMBER(G6),"FOUND","NOT_FOUND")))) -> INVALID | T6: =IF(AND($R6="sim",OR(I6="FOUND",I6="PARTIAL")),"INVALID",IF(I6<>"FOUND",I6,IF($C6="qualitativo",IF(J6="","NOT_FOUND",IF(ISNA(MATCH(J6,Parametros!$A$35:$A$39,0)),"INVALID",IF(ISNUMBER(VLOOKUP(J6,Parametros!$A$35:$B$39,2,FALSE())),"FOUND","NOT_FOUND"))),IF(ISNUMBER(J6),"FOUND","NOT_FOUND")))) -> FOUND | U6: =IF(AND($R6="sim",OR(L6="FOUND",L6="PARTIAL")),"INVALID",IF(L6<>"FOUND",L6,IF($C6="qualitativo",IF(M6="","NOT_FOUND",IF(ISNA(MATCH(M6,Parametros!$A$35:$A$39,0)),"INVALID",IF(ISNUMBER(VLOOKUP(M6,Parametros!$A$35:$B$39,2,FALSE())),"FOUND","NOT_FOUND"))),IF(ISNUMBER(M6),"FOUND","NOT_FOUND")))) -> FOUND | V6: =IF(S6<>"FOUND","",IF($C6="qualitativo",VLOOKUP(G6,Parametros!$A$35:$B$39,2,FALSE()),G6)) | W6: =IF(T6<>"FOUND","",IF($C6="qualitativo",VLOOKUP(J6,Parametros!$A$35:$B$39,2,FALSE()),J6)) -> 96 | X6: =IF(U6<>"FOUND","",IF($C6="qualitativo",VLOOKUP(M6,Parametros!$A$35:$B$39,2,FALSE()),M6)) -> 100 | Y6: =COUNT(V6:X6) -> 2 | Z6: =IF(Y6=0,"",MIN(V6:X6)) -> 96 | AA6: =IF(Y6=0,"",MAX(V6:X6)) -> 100 | AB6: =IF(NOT(ISNUMBER(E6)),"no_weight",IF(Y6=0,IF(AND(S6="INVALID",T6="INVALID",U6="INVALID"),"invalid_for_comparison","no_evidence"),IF(AND(Y6<3,Parametros!$B$50<>"SIM"),"missing_for_some_providers",IF(C6="qualitativo",IF(OR(Z6<0,AA6>1),"invalid_for_comparison",""),IF(D6="benefício",IF(AA6=0,"non_discriminative",IF(AA6<0,"invalid_for_comparison","")),IF(Z6<=0,"invalid_for_comparison","")))))) | AC6: =IF(AB6<>"","",IF(V6="",0,IF(C6="qualitativo",V6,IF(D6="minimização",Z6/V6,V6/AA6)))) -> 0 | AD6: =IF(AB6<>"","",IF(W6="",0,IF(C6="qualitativo",W6,IF(D6="minimização",Z6/W6,W6/AA6)))) -> 0.96 | AE6: =IF(AB6<>"","",IF(X6="",0,IF(C6="qualitativo",X6,IF(D6="minimização",Z6/X6,X6/AA6)))) -> 1 | AF6: =IF(AB6<>"","",IF(MAX(AC6:AE6)-MIN(AC6:AE6)<=Parametros!$B$47,"sim","não")) -> não | AG6: =IF(AB6<>"",AB6,IF(AND(AF6="sim",$B$23="sim"),"non_discriminative","")) | AH6: =IF(AG6="","sim","não") -> sim | AI6: =IF(ISNUMBER(AC6),AC6,0) -> 0 | AJ6: =IF(ISNUMBER(AD6),AD6,0) -> 0.96 | AK6: =IF(ISNUMBER(AE6),AE6,0) -> 1 | AL6: =IF(AH6="sim",1,0) -> 1 | AM6: =IF(AND(AH6="sim",Y6<3),TRIM(IF(V6="","AWS ","")&IF(W6="","Google ","")&IF(X6="","Azure","")),"") -> AWS
A7: Redução de emissões de gases de efeito estufa | B7: Sustentabilidade | C7: qualitativo | D7: absoluta | E7: =Pesos_Indicadores!H7 -> 0.017045455 | F7: FOUND | G7: alto | H7: 2026 | I7: FOUND | J7: alto | K7: 2026 | L7: FOUND | M7: alto | N7: 2026 | O7: =IF(AND(F7="FOUND",ISNUMBER(H7)),H7,"") -> 2026 | P7: =IF(AND(I7="FOUND",ISNUMBER(K7)),K7,"") -> 2026 | Q7: =IF(AND(L7="FOUND",ISNUMBER(N7)),N7,"") -> 2026 | R7: =IF(OR(Parametros!$B$46="",COUNT(O7:Q7)<2),"não",IF(MAX(O7:Q7)-MIN(O7:Q7)>Parametros!$B$46,"sim","não")) -> não | S7: =IF(AND($R7="sim",OR(F7="FOUND",F7="PARTIAL")),"INVALID",IF(F7<>"FOUND",F7,IF($C7="qualitativo",IF(G7="","NOT_FOUND",IF(ISNA(MATCH(G7,Parametros!$A$35:$A$39,0)),"INVALID",IF(ISNUMBER(VLOOKUP(G7,Parametros!$A$35:$B$39,2,FALSE())),"FOUND","NOT_FOUND"))),IF(ISNUMBER(G7),"FOUND","NOT_FOUND")))) -> FOUND | T7: =IF(AND($R7="sim",OR(I7="FOUND",I7="PARTIAL")),"INVALID",IF(I7<>"FOUND",I7,IF($C7="qualitativo",IF(J7="","NOT_FOUND",IF(ISNA(MATCH(J7,Parametros!$A$35:$A$39,0)),"INVALID",IF(ISNUMBER(VLOOKUP(J7,Parametros!$A$35:$B$39,2,FALSE())),"FOUND","NOT_FOUND"))),IF(ISNUMBER(J7),"FOUND","NOT_FOUND")))) -> FOUND | U7: =IF(AND($R7="sim",OR(L7="FOUND",L7="PARTIAL")),"INVALID",IF(L7<>"FOUND",L7,IF($C7="qualitativo",IF(M7="","NOT_FOUND",IF(ISNA(MATCH(M7,Parametros!$A$35:$A$39,0)),"INVALID",IF(ISNUMBER(VLOOKUP(M7,Parametros!$A$35:$B$39,2,FALSE())),"FOUND","NOT_FOUND"))),IF(ISNUMBER(M7),"FOUND","NOT_FOUND")))) -> FOUND | V7: =IF(S7<>"FOUND","",IF($C7="qualitativo",VLOOKUP(G7,Parametros!$A$35:$B$39,2,FALSE()),G7)) -> 0.75 | W7: =IF(T7<>"FOUND","",IF($C7="qualitativo",VLOOKUP(J7,Parametros!$A$35:$B$39,2,FALSE()),J7)) -> 0.75 | X7: =IF(U7<>"FOUND","",IF($C7="qualitativo",VLOOKUP(M7,Parametros!$A$35:$B$39,2,FALSE()),M7)) -> 0.75 | Y7: =COUNT(V7:X7) -> 3 | Z7: =IF(Y7=0,"",MIN(V7:X7)) -> 0.75 | AA7: =IF(Y7=0,"",MAX(V7:X7)) -> 0.75 | AB7: =IF(NOT(ISNUMBER(E7)),"no_weight",IF(Y7=0,IF(AND(S7="INVALID",T7="INVALID",U7="INVALID"),"invalid_for_comparison","no_evidence"),IF(AND(Y7<3,Parametros!$B$50<>"SIM"),"missing_for_some_providers",IF(C7="qualitativo",IF(OR(Z7<0,AA7>1),"invalid_for_comparison",""),IF(D7="benefício",IF(AA7=0,"non_discriminative",IF(AA7<0,"invalid_for_comparison","")),IF(Z7<=0,"invalid_for_comparison","")))))) | AC7: =IF(AB7<>"","",IF(V7="",0,IF(C7="qualitativo",V7,IF(D7="minimização",Z7/V7,V7/AA7)))) -> 0.75 | AD7: =IF(AB7<>"","",IF(W7="",0,IF(C7="qualitativo",W7,IF(D7="minimização",Z7/W7,W7/AA7)))) -> 0.75 | AE7: =IF(AB7<>"","",IF(X7="",0,IF(C7="qualitativo",X7,IF(D7="minimização",Z7/X7,X7/AA7)))) -> 0.75 | AF7: =IF(AB7<>"","",IF(MAX(AC7:AE7)-MIN(AC7:AE7)<=Parametros!$B$47,"sim","não")) -> sim | AG7: =IF(AB7<>"",AB7,IF(AND(AF7="sim",$B$23="sim"),"non_discriminative","")) | AH7: =IF(AG7="","sim","não") -> sim | AI7: =IF(ISNUMBER(AC7),AC7,0) -> 0.75 | AJ7: =IF(ISNUMBER(AD7),AD7,0) -> 0.75 | AK7: =IF(ISNUMBER(AE7),AE7,0) -> 0.75 | AL7: =IF(AH7="sim",1,0) -> 1 | AM7: =IF(AND(AH7="sim",Y7<3),TRIM(IF(V7="","AWS ","")&IF(W7="","Google ","")&IF(X7="","Azure","")),"")
A8: Gestão de resíduos eletrônicos (% de desvio de aterro) | B8: Sustentabilidade | C8: quantitativo | D8: benefício | E8: =Pesos_Indicadores!H8 -> 0.017045455 | F8: FOUND | G8: 84 | H8: 2026 | I8: FOUND | J8: 88 | K8: 2026 | L8: FOUND | M8: 92 | N8: 2026 | O8: =IF(AND(F8="FOUND",ISNUMBER(H8)),H8,"") -> 2026 | P8: =IF(AND(I8="FOUND",ISNUMBER(K8)),K8,"") -> 2026 | Q8: =IF(AND(L8="FOUND",ISNUMBER(N8)),N8,"") -> 2026 | R8: =IF(OR(Parametros!$B$46="",COUNT(O8:Q8)<2),"não",IF(MAX(O8:Q8)-MIN(O8:Q8)>Parametros!$B$46,"sim","não")) -> não | S8: =IF(AND($R8="sim",OR(F8="FOUND",F8="PARTIAL")),"INVALID",IF(F8<>"FOUND",F8,IF($C8="qualitativo",IF(G8="","NOT_FOUND",IF(ISNA(MATCH(G8,Parametros!$A$35:$A$39,0)),"INVALID",IF(ISNUMBER(VLOOKUP(G8,Parametros!$A$35:$B$39,2,FALSE())),"FOUND","NOT_FOUND"))),IF(ISNUMBER(G8),"FOUND","NOT_FOUND")))) -> FOUND | T8: =IF(AND($R8="sim",OR(I8="FOUND",I8="PARTIAL")),"INVALID",IF(I8<>"FOUND",I8,IF($C8="qualitativo",IF(J8="","NOT_FOUND",IF(ISNA(MATCH(J8,Parametros!$A$35:$A$39,0)),"INVALID",IF(ISNUMBER(VLOOKUP(J8,Parametros!$A$35:$B$39,2,FALSE())),"FOUND","NOT_FOUND"))),IF(ISNUMBER(J8),"FOUND","NOT_FOUND")))) -> FOUND | U8: =IF(AND($R8="sim",OR(L8="FOUND",L8="PARTIAL")),"INVALID",IF(L8<>"FOUND",L8,IF($C8="qualitativo",IF(M8="","NOT_FOUND",IF(ISNA(MATCH(M8,Parametros!$A$35:$A$39,0)),"INVALID",IF(ISNUMBER(VLOOKUP(M8,Parametros!$A$35:$B$39,2,FALSE())),"FOUND","NOT_FOUND"))),IF(ISNUMBER(M8),"FOUND","NOT_FOUND")))) -> FOUND | V8: =IF(S8<>"FOUND","",IF($C8="qualitativo",VLOOKUP(G8,Parametros!$A$35:$B$39,2,FALSE()),G8)) -> 84 | W8: =IF(T8<>"FOUND","",IF($C8="qualitativo",VLOOKUP(J8,Parametros!$A$35:$B$39,2,FALSE()),J8)) -> 88 | X8: =IF(U8<>"FOUND","",IF($C8="qualitativo",VLOOKUP(M8,Parametros!$A$35:$B$39,2,FALSE()),M8)) -> 92 | Y8: =COUNT(V8:X8) -> 3 | Z8: =IF(Y8=0,"",MIN(V8:X8)) -> 84 | AA8: =IF(Y8=0,"",MAX(V8:X8)) -> 92 | AB8: =IF(NOT(ISNUMBER(E8)),"no_weight",IF(Y8=0,IF(AND(S8="INVALID",T8="INVALID",U8="INVALID"),"invalid_for_comparison","no_evidence"),IF(AND(Y8<3,Parametros!$B$50<>"SIM"),"missing_for_some_providers",IF(C8="qualitativo",IF(OR(Z8<0,AA8>1),"invalid_for_comparison",""),IF(D8="benefício",IF(AA8=0,"non_discriminative",IF(AA8<0,"invalid_for_comparison","")),IF(Z8<=0,"invalid_for_comparison","")))))) | AC8: =IF(AB8<>"","",IF(V8="",0,IF(C8="qualitativo",V8,IF(D8="minimização",Z8/V8,V8/AA8)))) -> 0.91304348 | AD8: =IF(AB8<>"","",IF(W8="",0,IF(C8="qualitativo",W8,IF(D8="minimização",Z8/W8,W8/AA8)))) -> 0.95652174 | AE8: =IF(AB8<>"","",IF(X8="",0,IF(C8="qualitativo",X8,IF(D8="minimização",Z8/X8,X8/AA8)))) -> 1 | AF8: =IF(AB8<>"","",IF(MAX(AC8:AE8)-MIN(AC8:AE8)<=Parametros!$B$47,"sim","não")) -> não | AG8: =IF(AB8<>"",AB8,IF(AND(AF8="sim",$B$23="sim"),"non_discriminative","")) | AH8: =IF(AG8="","sim","não") -> sim | AI8: =IF(ISNUMBER(AC8),AC8,0) -> 0.91304348 | AJ8: =IF(ISNUMBER(AD8),AD8,0) -> 0.95652174 | AK8: =IF(ISNUMBER(AE8),AE8,0) -> 1 | AL8: =IF(AH8="sim",1,0) -> 1 | AM8: =IF(AND(AH8="sim",Y8<3),TRIM(IF(V8="","AWS ","")&IF(W8="","Google ","")&IF(X8="","Azure","")),"")
A9: Circularidade e ciclo de vida dos equipamentos | B9: Sustentabilidade | C9: qualitativo | D9: absoluta | E9: =Pesos_Indicadores!H9 -> 0.017045455 | F9: FOUND | G9: alto | H9: 2026 | I9: FOUND | J9: alto | K9: 2026 | L9: FOUND | M9: alto | N9: 2026 | O9: =IF(AND(F9="FOUND",ISNUMBER(H9)),H9,"") -> 2026 | P9: =IF(AND(I9="FOUND",ISNUMBER(K9)),K9,"") -> 2026 | Q9: =IF(AND(L9="FOUND",ISNUMBER(N9)),N9,"") -> 2026 | R9: =IF(OR(Parametros!$B$46="",COUNT(O9:Q9)<2),"não",IF(MAX(O9:Q9)-MIN(O9:Q9)>Parametros!$B$46,"sim","não")) -> não | S9: =IF(AND($R9="sim",OR(F9="FOUND",F9="PARTIAL")),"INVALID",IF(F9<>"FOUND",F9,IF($C9="qualitativo",IF(G9="","NOT_FOUND",IF(ISNA(MATCH(G9,Parametros!$A$35:$A$39,0)),"INVALID",IF(ISNUMBER(VLOOKUP(G9,Parametros!$A$35:$B$39,2,FALSE())),"FOUND","NOT_FOUND"))),IF(ISNUMBER(G9),"FOUND","NOT_FOUND")))) -> FOUND | T9: =IF(AND($R9="sim",OR(I9="FOUND",I9="PARTIAL")),"INVALID",IF(I9<>"FOUND",I9,IF($C9="qualitativo",IF(J9="","NOT_FOUND",IF(ISNA(MATCH(J9,Parametros!$A$35:$A$39,0)),"INVALID",IF(ISNUMBER(VLOOKUP(J9,Parametros!$A$35:$B$39,2,FALSE())),"FOUND","NOT_FOUND"))),IF(ISNUMBER(J9),"FOUND","NOT_FOUND")))) -> FOUND | U9: =IF(AND($R9="sim",OR(L9="FOUND",L9="PARTIAL")),"INVALID",IF(L9<>"FOUND",L9,IF($C9="qualitativo",IF(M9="","NOT_FOUND",IF(ISNA(MATCH(M9,Parametros!$A$35:$A$39,0)),"INVALID",IF(ISNUMBER(VLOOKUP(M9,Parametros!$A$35:$B$39,2,FALSE())),"FOUND","NOT_FOUND"))),IF(ISNUMBER(M9),"FOUND","NOT_FOUND")))) -> FOUND | V9: =IF(S9<>"FOUND","",IF($C9="qualitativo",VLOOKUP(G9,Parametros!$A$35:$B$39,2,FALSE()),G9)) -> 0.75 | W9: =IF(T9<>"FOUND","",IF($C9="qualitativo",VLOOKUP(J9,Parametros!$A$35:$B$39,2,FALSE()),J9)) -> 0.75 | X9: =IF(U9<>"FOUND","",IF($C9="qualitativo",VLOOKUP(M9,Parametros!$A$35:$B$39,2,FALSE()),M9)) -> 0.75 | Y9: =COUNT(V9:X9) -> 3 | Z9: =IF(Y9=0,"",MIN(V9:X9)) -> 0.75 | AA9: =IF(Y9=0,"",MAX(V9:X9)) -> 0.75 | AB9: =IF(NOT(ISNUMBER(E9)),"no_weight",IF(Y9=0,IF(AND(S9="INVALID",T9="INVALID",U9="INVALID"),"invalid_for_comparison","no_evidence"),IF(AND(Y9<3,Parametros!$B$50<>"SIM"),"missing_for_some_providers",IF(C9="qualitativo",IF(OR(Z9<0,AA9>1),"invalid_for_comparison",""),IF(D9="benefício",IF(AA9=0,"non_discriminative",IF(AA9<0,"invalid_for_comparison","")),IF(Z9<=0,"invalid_for_comparison","")))))) | AC9: =IF(AB9<>"","",IF(V9="",0,IF(C9="qualitativo",V9,IF(D9="minimização",Z9/V9,V9/AA9)))) -> 0.75 | AD9: =IF(AB9<>"","",IF(W9="",0,IF(C9="qualitativo",W9,IF(D9="minimização",Z9/W9,W9/AA9)))) -> 0.75 | AE9: =IF(AB9<>"","",IF(X9="",0,IF(C9="qualitativo",X9,IF(D9="minimização",Z9/X9,X9/AA9)))) -> 0.75 | AF9: =IF(AB9<>"","",IF(MAX(AC9:AE9)-MIN(AC9:AE9)<=Parametros!$B$47,"sim","não")) -> sim | AG9: =IF(AB9<>"",AB9,IF(AND(AF9="sim",$B$23="sim"),"non_discriminative","")) | AH9: =IF(AG9="","sim","não") -> sim | AI9: =IF(ISNUMBER(AC9),AC9,0) -> 0.75 | AJ9: =IF(ISNUMBER(AD9),AD9,0) -> 0.75 | AK9: =IF(ISNUMBER(AE9),AE9,0) -> 0.75 | AL9: =IF(AH9="sim",1,0) -> 1 | AM9: =IF(AND(AH9="sim",Y9<3),TRIM(IF(V9="","AWS ","")&IF(W9="","Google ","")&IF(X9="","Azure","")),"")
A10: Disponibilidade dos serviços (%) | B10: Desempenho Operacional | C10: quantitativo | D10: benefício | E10: =Pesos_Indicadores!H10 -> 0.027972028 | F10: FOUND | G10: 99.99 | H10: 2026 | I10: FOUND | J10: 99.99 | K10: 2026 | L10: FOUND | M10: 99.9 | N10: 2026 | O10: =IF(AND(F10="FOUND",ISNUMBER(H10)),H10,"") -> 2026 | P10: =IF(AND(I10="FOUND",ISNUMBER(K10)),K10,"") -> 2026 | Q10: =IF(AND(L10="FOUND",ISNUMBER(N10)),N10,"") -> 2026 | R10: =IF(OR(Parametros!$B$46="",COUNT(O10:Q10)<2),"não",IF(MAX(O10:Q10)-MIN(O10:Q10)>Parametros!$B$46,"sim","não")) -> não | S10: =IF(AND($R10="sim",OR(F10="FOUND",F10="PARTIAL")),"INVALID",IF(F10<>"FOUND",F10,IF($C10="qualitativo",IF(G10="","NOT_FOUND",IF(ISNA(MATCH(G10,Parametros!$A$35:$A$39,0)),"INVALID",IF(ISNUMBER(VLOOKUP(G10,Parametros!$A$35:$B$39,2,FALSE())),"FOUND","NOT_FOUND"))),IF(ISNUMBER(G10),"FOUND","NOT_FOUND")))) -> FOUND | T10: =IF(AND($R10="sim",OR(I10="FOUND",I10="PARTIAL")),"INVALID",IF(I10<>"FOUND",I10,IF($C10="qualitativo",IF(J10="","NOT_FOUND",IF(ISNA(MATCH(J10,Parametros!$A$35:$A$39,0)),"INVALID",IF(ISNUMBER(VLOOKUP(J10,Parametros!$A$35:$B$39,2,FALSE())),"FOUND","NOT_FOUND"))),IF(ISNUMBER(J10),"FOUND","NOT_FOUND")))) -> FOUND | U10: =IF(AND($R10="sim",OR(L10="FOUND",L10="PARTIAL")),"INVALID",IF(L10<>"FOUND",L10,IF($C10="qualitativo",IF(M10="","NOT_FOUND",IF(ISNA(MATCH(M10,Parametros!$A$35:$A$39,0)),"INVALID",IF(ISNUMBER(VLOOKUP(M10,Parametros!$A$35:$B$39,2,FALSE())),"FOUND","NOT_FOUND"))),IF(ISNUMBER(M10),"FOUND","NOT_FOUND")))) -> FOUND | V10: =IF(S10<>"FOUND","",IF($C10="qualitativo",VLOOKUP(G10,Parametros!$A$35:$B$39,2,FALSE()),G10)) -> 99.99 | W10: =IF(T10<>"FOUND","",IF($C10="qualitativo",VLOOKUP(J10,Parametros!$A$35:$B$39,2,FALSE()),J10)) -> 99.99 | X10: =IF(U10<>"FOUND","",IF($C10="qualitativo",VLOOKUP(M10,Parametros!$A$35:$B$39,2,FALSE()),M10)) -> 99.9 | Y10: =COUNT(V10:X10) -> 3 | Z10: =IF(Y10=0,"",MIN(V10:X10)) -> 99.9 | AA10: =IF(Y10=0,"",MAX(V10:X10)) -> 99.99 | AB10: =IF(NOT(ISNUMBER(E10)),"no_weight",IF(Y10=0,IF(AND(S10="INVALID",T10="INVALID",U10="INVALID"),"invalid_for_comparison","no_evidence"),IF(AND(Y10<3,Parametros!$B$50<>"SIM"),"missing_for_some_providers",IF(C10="qualitativo",IF(OR(Z10<0,AA10>1),"invalid_for_comparison",""),IF(D10="benefício",IF(AA10=0,"non_discriminative",IF(AA10<0,"invalid_for_comparison","")),IF(Z10<=0,"invalid_for_comparison","")))))) | AC10: =IF(AB10<>"","",IF(V10="",0,IF(C10="qualitativo",V10,IF(D10="minimização",Z10/V10,V10/AA10)))) -> 1 | AD10: =IF(AB10<>"","",IF(W10="",0,IF(C10="qualitativo",W10,IF(D10="minimização",Z10/W10,W10/AA10)))) -> 1 | AE10: =IF(AB10<>"","",IF(X10="",0,IF(C10="qualitativo",X10,IF(D10="minimização",Z10/X10,X10/AA10)))) -> 0.99909991 | AF10: =IF(AB10<>"","",IF(MAX(AC10:AE10)-MIN(AC10:AE10)<=Parametros!$B$47,"sim","não")) -> não | AG10: =IF(AB10<>"",AB10,IF(AND(AF10="sim",$B$23="sim"),"non_discriminative","")) | AH10: =IF(AG10="","sim","não") -> sim | AI10: =IF(ISNUMBER(AC10),AC10,0) -> 1 | AJ10: =IF(ISNUMBER(AD10),AD10,0) -> 1 | AK10: =IF(ISNUMBER(AE10),AE10,0) -> 0.99909991 | AL10: =IF(AH10="sim",1,0) -> 1 | AM10: =IF(AND(AH10="sim",Y10<3),TRIM(IF(V10="","AWS ","")&IF(W10="","Google ","")&IF(X10="","Azure","")),"")
A11: Suporte técnico e resposta a incidentes | B11: Desempenho Operacional | C11: qualitativo | D11: absoluta | E11: =Pesos_Indicadores!H11 -> 0.020979021 | F11: FOUND | G11: alto | H11: 2026 | I11: FOUND | J11: alto | K11: 2026 | L11: FOUND | M11: alto | N11: 2026 | O11: =IF(AND(F11="FOUND",ISNUMBER(H11)),H11,"") -> 2026 | P11: =IF(AND(I11="FOUND",ISNUMBER(K11)),K11,"") -> 2026 | Q11: =IF(AND(L11="FOUND",ISNUMBER(N11)),N11,"") -> 2026 | R11: =IF(OR(Parametros!$B$46="",COUNT(O11:Q11)<2),"não",IF(MAX(O11:Q11)-MIN(O11:Q11)>Parametros!$B$46,"sim","não")) -> não | S11: =IF(AND($R11="sim",OR(F11="FOUND",F11="PARTIAL")),"INVALID",IF(F11<>"FOUND",F11,IF($C11="qualitativo",IF(G11="","NOT_FOUND",IF(ISNA(MATCH(G11,Parametros!$A$35:$A$39,0)),"INVALID",IF(ISNUMBER(VLOOKUP(G11,Parametros!$A$35:$B$39,2,FALSE())),"FOUND","NOT_FOUND"))),IF(ISNUMBER(G11),"FOUND","NOT_FOUND")))) -> FOUND | T11: =IF(AND($R11="sim",OR(I11="FOUND",I11="PARTIAL")),"INVALID",IF(I11<>"FOUND",I11,IF($C11="qualitativo",IF(J11="","NOT_FOUND",IF(ISNA(MATCH(J11,Parametros!$A$35:$A$39,0)),"INVALID",IF(ISNUMBER(VLOOKUP(J11,Parametros!$A$35:$B$39,2,FALSE())),"FOUND","NOT_FOUND"))),IF(ISNUMBER(J11),"FOUND","NOT_FOUND")))) -> FOUND | U11: =IF(AND($R11="sim",OR(L11="FOUND",L11="PARTIAL")),"INVALID",IF(L11<>"FOUND",L11,IF($C11="qualitativo",IF(M11="","NOT_FOUND",IF(ISNA(MATCH(M11,Parametros!$A$35:$A$39,0)),"INVALID",IF(ISNUMBER(VLOOKUP(M11,Parametros!$A$35:$B$39,2,FALSE())),"FOUND","NOT_FOUND"))),IF(ISNUMBER(M11),"FOUND","NOT_FOUND")))) -> FOUND | V11: =IF(S11<>"FOUND","",IF($C11="qualitativo",VLOOKUP(G11,Parametros!$A$35:$B$39,2,FALSE()),G11)) -> 0.75 | W11: =IF(T11<>"FOUND","",IF($C11="qualitativo",VLOOKUP(J11,Parametros!$A$35:$B$39,2,FALSE()),J11)) -> 0.75 | X11: =IF(U11<>"FOUND","",IF($C11="qualitativo",VLOOKUP(M11,Parametros!$A$35:$B$39,2,FALSE()),M11)) -> 0.75 | Y11: =COUNT(V11:X11) -> 3 | Z11: =IF(Y11=0,"",MIN(V11:X11)) -> 0.75 | AA11: =IF(Y11=0,"",MAX(V11:X11)) -> 0.75 | AB11: =IF(NOT(ISNUMBER(E11)),"no_weight",IF(Y11=0,IF(AND(S11="INVALID",T11="INVALID",U11="INVALID"),"invalid_for_comparison","no_evidence"),IF(AND(Y11<3,Parametros!$B$50<>"SIM"),"missing_for_some_providers",IF(C11="qualitativo",IF(OR(Z11<0,AA11>1),"invalid_for_comparison",""),IF(D11="benefício",IF(AA11=0,"non_discriminative",IF(AA11<0,"invalid_for_comparison","")),IF(Z11<=0,"invalid_for_comparison","")))))) | AC11: =IF(AB11<>"","",IF(V11="",0,IF(C11="qualitativo",V11,IF(D11="minimização",Z11/V11,V11/AA11)))) -> 0.75 | AD11: =IF(AB11<>"","",IF(W11="",0,IF(C11="qualitativo",W11,IF(D11="minimização",Z11/W11,W11/AA11)))) -> 0.75 | AE11: =IF(AB11<>"","",IF(X11="",0,IF(C11="qualitativo",X11,IF(D11="minimização",Z11/X11,X11/AA11)))) -> 0.75 | AF11: =IF(AB11<>"","",IF(MAX(AC11:AE11)-MIN(AC11:AE11)<=Parametros!$B$47,"sim","não")) -> sim | AG11: =IF(AB11<>"",AB11,IF(AND(AF11="sim",$B$23="sim"),"non_discriminative","")) | AH11: =IF(AG11="","sim","não") -> sim | AI11: =IF(ISNUMBER(AC11),AC11,0) -> 0.75 | AJ11: =IF(ISNUMBER(AD11),AD11,0) -> 0.75 | AK11: =IF(ISNUMBER(AE11),AE11,0) -> 0.75 | AL11: =IF(AH11="sim",1,0) -> 1 | AM11: =IF(AND(AH11="sim",Y11<3),TRIM(IF(V11="","AWS ","")&IF(W11="","Google ","")&IF(X11="","Azure","")),"")
A12: Latência e tempo de resposta (ms) | B12: Desempenho Operacional | C12: quantitativo | D12: minimização | E12: =Pesos_Indicadores!H12 -> 0.020979021 | F12: NOT_FOUND | I12: NOT_FOUND | L12: INVALID | O12: =IF(AND(F12="FOUND",ISNUMBER(H12)),H12,"") | P12: =IF(AND(I12="FOUND",ISNUMBER(K12)),K12,"") | Q12: =IF(AND(L12="FOUND",ISNUMBER(N12)),N12,"") | R12: =IF(OR(Parametros!$B$46="",COUNT(O12:Q12)<2),"não",IF(MAX(O12:Q12)-MIN(O12:Q12)>Parametros!$B$46,"sim","não")) -> não | S12: =IF(AND($R12="sim",OR(F12="FOUND",F12="PARTIAL")),"INVALID",IF(F12<>"FOUND",F12,IF($C12="qualitativo",IF(G12="","NOT_FOUND",IF(ISNA(MATCH(G12,Parametros!$A$35:$A$39,0)),"INVALID",IF(ISNUMBER(VLOOKUP(G12,Parametros!$A$35:$B$39,2,FALSE())),"FOUND","NOT_FOUND"))),IF(ISNUMBER(G12),"FOUND","NOT_FOUND")))) -> NOT_FOUND | T12: =IF(AND($R12="sim",OR(I12="FOUND",I12="PARTIAL")),"INVALID",IF(I12<>"FOUND",I12,IF($C12="qualitativo",IF(J12="","NOT_FOUND",IF(ISNA(MATCH(J12,Parametros!$A$35:$A$39,0)),"INVALID",IF(ISNUMBER(VLOOKUP(J12,Parametros!$A$35:$B$39,2,FALSE())),"FOUND","NOT_FOUND"))),IF(ISNUMBER(J12),"FOUND","NOT_FOUND")))) -> NOT_FOUND | U12: =IF(AND($R12="sim",OR(L12="FOUND",L12="PARTIAL")),"INVALID",IF(L12<>"FOUND",L12,IF($C12="qualitativo",IF(M12="","NOT_FOUND",IF(ISNA(MATCH(M12,Parametros!$A$35:$A$39,0)),"INVALID",IF(ISNUMBER(VLOOKUP(M12,Parametros!$A$35:$B$39,2,FALSE())),"FOUND","NOT_FOUND"))),IF(ISNUMBER(M12),"FOUND","NOT_FOUND")))) -> INVALID | V12: =IF(S12<>"FOUND","",IF($C12="qualitativo",VLOOKUP(G12,Parametros!$A$35:$B$39,2,FALSE()),G12)) | W12: =IF(T12<>"FOUND","",IF($C12="qualitativo",VLOOKUP(J12,Parametros!$A$35:$B$39,2,FALSE()),J12)) | X12: =IF(U12<>"FOUND","",IF($C12="qualitativo",VLOOKUP(M12,Parametros!$A$35:$B$39,2,FALSE()),M12)) | Y12: =COUNT(V12:X12) -> 0 | Z12: =IF(Y12=0,"",MIN(V12:X12)) | AA12: =IF(Y12=0,"",MAX(V12:X12)) | AB12: =IF(NOT(ISNUMBER(E12)),"no_weight",IF(Y12=0,IF(AND(S12="INVALID",T12="INVALID",U12="INVALID"),"invalid_for_comparison","no_evidence"),IF(AND(Y12<3,Parametros!$B$50<>"SIM"),"missing_for_some_providers",IF(C12="qualitativo",IF(OR(Z12<0,AA12>1),"invalid_for_comparison",""),IF(D12="benefício",IF(AA12=0,"non_discriminative",IF(AA12<0,"invalid_for_comparison","")),IF(Z12<=0,"invalid_for_comparison","")))))) -> no_evidence | AC12: =IF(AB12<>"","",IF(V12="",0,IF(C12="qualitativo",V12,IF(D12="minimização",Z12/V12,V12/AA12)))) | AD12: =IF(AB12<>"","",IF(W12="",0,IF(C12="qualitativo",W12,IF(D12="minimização",Z12/W12,W12/AA12)))) | AE12: =IF(AB12<>"","",IF(X12="",0,IF(C12="qualitativo",X12,IF(D12="minimização",Z12/X12,X12/AA12)))) | AF12: =IF(AB12<>"","",IF(MAX(AC12:AE12)-MIN(AC12:AE12)<=Parametros!$B$47,"sim","não")) | AG12: =IF(AB12<>"",AB12,IF(AND(AF12="sim",$B$23="sim"),"non_discriminative","")) -> no_evidence | AH12: =IF(AG12="","sim","não") -> não | AI12: =IF(ISNUMBER(AC12),AC12,0) -> 0 | AJ12: =IF(ISNUMBER(AD12),AD12,0) -> 0 | AK12: =IF(ISNUMBER(AE12),AE12,0) -> 0 | AL12: =IF(AH12="sim",1,0) -> 0 | AM12: =IF(AND(AH12="sim",Y12<3),TRIM(IF(V12="","AWS ","")&IF(W12="","Google ","")&IF(X12="","Azure","")),"")
A13: Escalabilidade e elasticidade | B13: Desempenho Operacional | C13: qualitativo | D13: absoluta | E13: =Pesos_Indicadores!H13 -> 0.020979021 | F13: FOUND | G13: alto | H13: 2026 | I13: FOUND | J13: alto | K13: 2026 | L13: FOUND | M13: alto | N13: 2026 | O13: =IF(AND(F13="FOUND",ISNUMBER(H13)),H13,"") -> 2026 | P13: =IF(AND(I13="FOUND",ISNUMBER(K13)),K13,"") -> 2026 | Q13: =IF(AND(L13="FOUND",ISNUMBER(N13)),N13,"") -> 2026 | R13: =IF(OR(Parametros!$B$46="",COUNT(O13:Q13)<2),"não",IF(MAX(O13:Q13)-MIN(O13:Q13)>Parametros!$B$46,"sim","não")) -> não | S13: =IF(AND($R13="sim",OR(F13="FOUND",F13="PARTIAL")),"INVALID",IF(F13<>"FOUND",F13,IF($C13="qualitativo",IF(G13="","NOT_FOUND",IF(ISNA(MATCH(G13,Parametros!$A$35:$A$39,0)),"INVALID",IF(ISNUMBER(VLOOKUP(G13,Parametros!$A$35:$B$39,2,FALSE())),"FOUND","NOT_FOUND"))),IF(ISNUMBER(G13),"FOUND","NOT_FOUND")))) -> FOUND | T13: =IF(AND($R13="sim",OR(I13="FOUND",I13="PARTIAL")),"INVALID",IF(I13<>"FOUND",I13,IF($C13="qualitativo",IF(J13="","NOT_FOUND",IF(ISNA(MATCH(J13,Parametros!$A$35:$A$39,0)),"INVALID",IF(ISNUMBER(VLOOKUP(J13,Parametros!$A$35:$B$39,2,FALSE())),"FOUND","NOT_FOUND"))),IF(ISNUMBER(J13),"FOUND","NOT_FOUND")))) -> FOUND | U13: =IF(AND($R13="sim",OR(L13="FOUND",L13="PARTIAL")),"INVALID",IF(L13<>"FOUND",L13,IF($C13="qualitativo",IF(M13="","NOT_FOUND",IF(ISNA(MATCH(M13,Parametros!$A$35:$A$39,0)),"INVALID",IF(ISNUMBER(VLOOKUP(M13,Parametros!$A$35:$B$39,2,FALSE())),"FOUND","NOT_FOUND"))),IF(ISNUMBER(M13),"FOUND","NOT_FOUND")))) -> FOUND | V13: =IF(S13<>"FOUND","",IF($C13="qualitativo",VLOOKUP(G13,Parametros!$A$35:$B$39,2,FALSE()),G13)) -> 0.75 | W13: =IF(T13<>"FOUND","",IF($C13="qualitativo",VLOOKUP(J13,Parametros!$A$35:$B$39,2,FALSE()),J13)) -> 0.75 | X13: =IF(U13<>"FOUND","",IF($C13="qualitativo",VLOOKUP(M13,Parametros!$A$35:$B$39,2,FALSE()),M13)) -> 0.75 | Y13: =COUNT(V13:X13) -> 3 | Z13: =IF(Y13=0,"",MIN(V13:X13)) -> 0.75 | AA13: =IF(Y13=0,"",MAX(V13:X13)) -> 0.75 | AB13: =IF(NOT(ISNUMBER(E13)),"no_weight",IF(Y13=0,IF(AND(S13="INVALID",T13="INVALID",U13="INVALID"),"invalid_for_comparison","no_evidence"),IF(AND(Y13<3,Parametros!$B$50<>"SIM"),"missing_for_some_providers",IF(C13="qualitativo",IF(OR(Z13<0,AA13>1),"invalid_for_comparison",""),IF(D13="benefício",IF(AA13=0,"non_discriminative",IF(AA13<0,"invalid_for_comparison","")),IF(Z13<=0,"invalid_for_comparison","")))))) | AC13: =IF(AB13<>"","",IF(V13="",0,IF(C13="qualitativo",V13,IF(D13="minimização",Z13/V13,V13/AA13)))) -> 0.75 | AD13: =IF(AB13<>"","",IF(W13="",0,IF(C13="qualitativo",W13,IF(D13="minimização",Z13/W13,W13/AA13)))) -> 0.75 | AE13: =IF(AB13<>"","",IF(X13="",0,IF(C13="qualitativo",X13,IF(D13="minimização",Z13/X13,X13/AA13)))) -> 0.75 | AF13: =IF(AB13<>"","",IF(MAX(AC13:AE13)-MIN(AC13:AE13)<=Parametros!$B$47,"sim","não")) -> sim | AG13: =IF(AB13<>"",AB13,IF(AND(AF13="sim",$B$23="sim"),"non_discriminative","")) | AH13: =IF(AG13="","sim","não") -> sim | AI13: =IF(ISNUMBER(AC13),AC13,0) -> 0.75 | AJ13: =IF(ISNUMBER(AD13),AD13,0) -> 0.75 | AK13: =IF(ISNUMBER(AE13),AE13,0) -> 0.75 | AL13: =IF(AH13="sim",1,0) -> 1 | AM13: =IF(AND(AH13="sim",Y13<3),TRIM(IF(V13="","AWS ","")&IF(W13="","Google ","")&IF(X13="","Azure","")),"")
A14: Certificações e conformidade | B14: Segurança da Informação | C14: qualitativo | D14: absoluta | E14: =Pesos_Indicadores!H14 -> 0.20454545 | F14: FOUND | G14: alto | H14: 2026 | I14: FOUND | J14: alto | K14: 2026 | L14: FOUND | M14: completo | N14: 2026 | O14: =IF(AND(F14="FOUND",ISNUMBER(H14)),H14,"") -> 2026 | P14: =IF(AND(I14="FOUND",ISNUMBER(K14)),K14,"") -> 2026 | Q14: =IF(AND(L14="FOUND",ISNUMBER(N14)),N14,"") -> 2026 | R14: =IF(OR(Parametros!$B$46="",COUNT(O14:Q14)<2),"não",IF(MAX(O14:Q14)-MIN(O14:Q14)>Parametros!$B$46,"sim","não")) -> não | S14: =IF(AND($R14="sim",OR(F14="FOUND",F14="PARTIAL")),"INVALID",IF(F14<>"FOUND",F14,IF($C14="qualitativo",IF(G14="","NOT_FOUND",IF(ISNA(MATCH(G14,Parametros!$A$35:$A$39,0)),"INVALID",IF(ISNUMBER(VLOOKUP(G14,Parametros!$A$35:$B$39,2,FALSE())),"FOUND","NOT_FOUND"))),IF(ISNUMBER(G14),"FOUND","NOT_FOUND")))) -> FOUND | T14: =IF(AND($R14="sim",OR(I14="FOUND",I14="PARTIAL")),"INVALID",IF(I14<>"FOUND",I14,IF($C14="qualitativo",IF(J14="","NOT_FOUND",IF(ISNA(MATCH(J14,Parametros!$A$35:$A$39,0)),"INVALID",IF(ISNUMBER(VLOOKUP(J14,Parametros!$A$35:$B$39,2,FALSE())),"FOUND","NOT_FOUND"))),IF(ISNUMBER(J14),"FOUND","NOT_FOUND")))) -> FOUND | U14: =IF(AND($R14="sim",OR(L14="FOUND",L14="PARTIAL")),"INVALID",IF(L14<>"FOUND",L14,IF($C14="qualitativo",IF(M14="","NOT_FOUND",IF(ISNA(MATCH(M14,Parametros!$A$35:$A$39,0)),"INVALID",IF(ISNUMBER(VLOOKUP(M14,Parametros!$A$35:$B$39,2,FALSE())),"FOUND","NOT_FOUND"))),IF(ISNUMBER(M14),"FOUND","NOT_FOUND")))) -> FOUND | V14: =IF(S14<>"FOUND","",IF($C14="qualitativo",VLOOKUP(G14,Parametros!$A$35:$B$39,2,FALSE()),G14)) -> 0.75 | W14: =IF(T14<>"FOUND","",IF($C14="qualitativo",VLOOKUP(J14,Parametros!$A$35:$B$39,2,FALSE()),J14)) -> 0.75 | X14: =IF(U14<>"FOUND","",IF($C14="qualitativo",VLOOKUP(M14,Parametros!$A$35:$B$39,2,FALSE()),M14)) -> 1 | Y14: =COUNT(V14:X14) -> 3 | Z14: =IF(Y14=0,"",MIN(V14:X14)) -> 0.75 | AA14: =IF(Y14=0,"",MAX(V14:X14)) -> 1 | AB14: =IF(NOT(ISNUMBER(E14)),"no_weight",IF(Y14=0,IF(AND(S14="INVALID",T14="INVALID",U14="INVALID"),"invalid_for_comparison","no_evidence"),IF(AND(Y14<3,Parametros!$B$50<>"SIM"),"missing_for_some_providers",IF(C14="qualitativo",IF(OR(Z14<0,AA14>1),"invalid_for_comparison",""),IF(D14="benefício",IF(AA14=0,"non_discriminative",IF(AA14<0,"invalid_for_comparison","")),IF(Z14<=0,"invalid_for_comparison","")))))) | AC14: =IF(AB14<>"","",IF(V14="",0,IF(C14="qualitativo",V14,IF(D14="minimização",Z14/V14,V14/AA14)))) -> 0.75 | AD14: =IF(AB14<>"","",IF(W14="",0,IF(C14="qualitativo",W14,IF(D14="minimização",Z14/W14,W14/AA14)))) -> 0.75 | AE14: =IF(AB14<>"","",IF(X14="",0,IF(C14="qualitativo",X14,IF(D14="minimização",Z14/X14,X14/AA14)))) -> 1 | AF14: =IF(AB14<>"","",IF(MAX(AC14:AE14)-MIN(AC14:AE14)<=Parametros!$B$47,"sim","não")) -> não | AG14: =IF(AB14<>"",AB14,IF(AND(AF14="sim",$B$23="sim"),"non_discriminative","")) | AH14: =IF(AG14="","sim","não") -> sim | AI14: =IF(ISNUMBER(AC14),AC14,0) -> 0.75 | AJ14: =IF(ISNUMBER(AD14),AD14,0) -> 0.75 | AK14: =IF(ISNUMBER(AE14),AE14,0) -> 1 | AL14: =IF(AH14="sim",1,0) -> 1 | AM14: =IF(AND(AH14="sim",Y14<3),TRIM(IF(V14="","AWS ","")&IF(W14="","Google ","")&IF(X14="","Azure","")),"")
A15: Backup, recuperação de desastres e continuidade | B15: Segurança da Informação | C15: qualitativo | D15: absoluta | E15: =Pesos_Indicadores!H15 -> 0.20454545 | F15: FOUND | G15: alto | H15: 2026 | I15: FOUND | J15: alto | K15: 2026 | L15: FOUND | M15: alto | N15: 2026 | O15: =IF(AND(F15="FOUND",ISNUMBER(H15)),H15,"") -> 2026 | P15: =IF(AND(I15="FOUND",ISNUMBER(K15)),K15,"") -> 2026 | Q15: =IF(AND(L15="FOUND",ISNUMBER(N15)),N15,"") -> 2026 | R15: =IF(OR(Parametros!$B$46="",COUNT(O15:Q15)<2),"não",IF(MAX(O15:Q15)-MIN(O15:Q15)>Parametros!$B$46,"sim","não")) -> não | S15: =IF(AND($R15="sim",OR(F15="FOUND",F15="PARTIAL")),"INVALID",IF(F15<>"FOUND",F15,IF($C15="qualitativo",IF(G15="","NOT_FOUND",IF(ISNA(MATCH(G15,Parametros!$A$35:$A$39,0)),"INVALID",IF(ISNUMBER(VLOOKUP(G15,Parametros!$A$35:$B$39,2,FALSE())),"FOUND","NOT_FOUND"))),IF(ISNUMBER(G15),"FOUND","NOT_FOUND")))) -> FOUND | T15: =IF(AND($R15="sim",OR(I15="FOUND",I15="PARTIAL")),"INVALID",IF(I15<>"FOUND",I15,IF($C15="qualitativo",IF(J15="","NOT_FOUND",IF(ISNA(MATCH(J15,Parametros!$A$35:$A$39,0)),"INVALID",IF(ISNUMBER(VLOOKUP(J15,Parametros!$A$35:$B$39,2,FALSE())),"FOUND","NOT_FOUND"))),IF(ISNUMBER(J15),"FOUND","NOT_FOUND")))) -> FOUND | U15: =IF(AND($R15="sim",OR(L15="FOUND",L15="PARTIAL")),"INVALID",IF(L15<>"FOUND",L15,IF($C15="qualitativo",IF(M15="","NOT_FOUND",IF(ISNA(MATCH(M15,Parametros!$A$35:$A$39,0)),"INVALID",IF(ISNUMBER(VLOOKUP(M15,Parametros!$A$35:$B$39,2,FALSE())),"FOUND","NOT_FOUND"))),IF(ISNUMBER(M15),"FOUND","NOT_FOUND")))) -> FOUND | V15: =IF(S15<>"FOUND","",IF($C15="qualitativo",VLOOKUP(G15,Parametros!$A$35:$B$39,2,FALSE()),G15)) -> 0.75 | W15: =IF(T15<>"FOUND","",IF($C15="qualitativo",VLOOKUP(J15,Parametros!$A$35:$B$39,2,FALSE()),J15)) -> 0.75 | X15: =IF(U15<>"FOUND","",IF($C15="qualitativo",VLOOKUP(M15,Parametros!$A$35:$B$39,2,FALSE()),M15)) -> 0.75 | Y15: =COUNT(V15:X15) -> 3 | Z15: =IF(Y15=0,"",MIN(V15:X15)) -> 0.75 | AA15: =IF(Y15=0,"",MAX(V15:X15)) -> 0.75 | AB15: =IF(NOT(ISNUMBER(E15)),"no_weight",IF(Y15=0,IF(AND(S15="INVALID",T15="INVALID",U15="INVALID"),"invalid_for_comparison","no_evidence"),IF(AND(Y15<3,Parametros!$B$50<>"SIM"),"missing_for_some_providers",IF(C15="qualitativo",IF(OR(Z15<0,AA15>1),"invalid_for_comparison",""),IF(D15="benefício",IF(AA15=0,"non_discriminative",IF(AA15<0,"invalid_for_comparison","")),IF(Z15<=0,"invalid_for_comparison","")))))) | AC15: =IF(AB15<>"","",IF(V15="",0,IF(C15="qualitativo",V15,IF(D15="minimização",Z15/V15,V15/AA15)))) -> 0.75 | AD15: =IF(AB15<>"","",IF(W15="",0,IF(C15="qualitativo",W15,IF(D15="minimização",Z15/W15,W15/AA15)))) -> 0.75 | AE15: =IF(AB15<>"","",IF(X15="",0,IF(C15="qualitativo",X15,IF(D15="minimização",Z15/X15,X15/AA15)))) -> 0.75 | AF15: =IF(AB15<>"","",IF(MAX(AC15:AE15)-MIN(AC15:AE15)<=Parametros!$B$47,"sim","não")) -> sim | AG15: =IF(AB15<>"",AB15,IF(AND(AF15="sim",$B$23="sim"),"non_discriminative","")) | AH15: =IF(AG15="","sim","não") -> sim | AI15: =IF(ISNUMBER(AC15),AC15,0) -> 0.75 | AJ15: =IF(ISNUMBER(AD15),AD15,0) -> 0.75 | AK15: =IF(ISNUMBER(AE15),AE15,0) -> 0.75 | AL15: =IF(AH15="sim",1,0) -> 1 | AM15: =IF(AND(AH15="sim",Y15<3),TRIM(IF(V15="","AWS ","")&IF(W15="","Google ","")&IF(X15="","Azure","")),"")
A16: Identidade, autenticação e controle de acesso | B16: Segurança da Informação | C16: qualitativo | D16: absoluta | E16: =Pesos_Indicadores!H16 -> 0.20454545 | F16: FOUND | G16: alto | H16: 2026 | I16: FOUND | J16: alto | K16: 2026 | L16: FOUND | M16: alto | N16: 2026 | O16: =IF(AND(F16="FOUND",ISNUMBER(H16)),H16,"") -> 2026 | P16: =IF(AND(I16="FOUND",ISNUMBER(K16)),K16,"") -> 2026 | Q16: =IF(AND(L16="FOUND",ISNUMBER(N16)),N16,"") -> 2026 | R16: =IF(OR(Parametros!$B$46="",COUNT(O16:Q16)<2),"não",IF(MAX(O16:Q16)-MIN(O16:Q16)>Parametros!$B$46,"sim","não")) -> não | S16: =IF(AND($R16="sim",OR(F16="FOUND",F16="PARTIAL")),"INVALID",IF(F16<>"FOUND",F16,IF($C16="qualitativo",IF(G16="","NOT_FOUND",IF(ISNA(MATCH(G16,Parametros!$A$35:$A$39,0)),"INVALID",IF(ISNUMBER(VLOOKUP(G16,Parametros!$A$35:$B$39,2,FALSE())),"FOUND","NOT_FOUND"))),IF(ISNUMBER(G16),"FOUND","NOT_FOUND")))) -> FOUND | T16: =IF(AND($R16="sim",OR(I16="FOUND",I16="PARTIAL")),"INVALID",IF(I16<>"FOUND",I16,IF($C16="qualitativo",IF(J16="","NOT_FOUND",IF(ISNA(MATCH(J16,Parametros!$A$35:$A$39,0)),"INVALID",IF(ISNUMBER(VLOOKUP(J16,Parametros!$A$35:$B$39,2,FALSE())),"FOUND","NOT_FOUND"))),IF(ISNUMBER(J16),"FOUND","NOT_FOUND")))) -> FOUND | U16: =IF(AND($R16="sim",OR(L16="FOUND",L16="PARTIAL")),"INVALID",IF(L16<>"FOUND",L16,IF($C16="qualitativo",IF(M16="","NOT_FOUND",IF(ISNA(MATCH(M16,Parametros!$A$35:$A$39,0)),"INVALID",IF(ISNUMBER(VLOOKUP(M16,Parametros!$A$35:$B$39,2,FALSE())),"FOUND","NOT_FOUND"))),IF(ISNUMBER(M16),"FOUND","NOT_FOUND")))) -> FOUND | V16: =IF(S16<>"FOUND","",IF($C16="qualitativo",VLOOKUP(G16,Parametros!$A$35:$B$39,2,FALSE()),G16)) -> 0.75 | W16: =IF(T16<>"FOUND","",IF($C16="qualitativo",VLOOKUP(J16,Parametros!$A$35:$B$39,2,FALSE()),J16)) -> 0.75 | X16: =IF(U16<>"FOUND","",IF($C16="qualitativo",VLOOKUP(M16,Parametros!$A$35:$B$39,2,FALSE()),M16)) -> 0.75 | Y16: =COUNT(V16:X16) -> 3 | Z16: =IF(Y16=0,"",MIN(V16:X16)) -> 0.75 | AA16: =IF(Y16=0,"",MAX(V16:X16)) -> 0.75 | AB16: =IF(NOT(ISNUMBER(E16)),"no_weight",IF(Y16=0,IF(AND(S16="INVALID",T16="INVALID",U16="INVALID"),"invalid_for_comparison","no_evidence"),IF(AND(Y16<3,Parametros!$B$50<>"SIM"),"missing_for_some_providers",IF(C16="qualitativo",IF(OR(Z16<0,AA16>1),"invalid_for_comparison",""),IF(D16="benefício",IF(AA16=0,"non_discriminative",IF(AA16<0,"invalid_for_comparison","")),IF(Z16<=0,"invalid_for_comparison","")))))) | AC16: =IF(AB16<>"","",IF(V16="",0,IF(C16="qualitativo",V16,IF(D16="minimização",Z16/V16,V16/AA16)))) -> 0.75 | AD16: =IF(AB16<>"","",IF(W16="",0,IF(C16="qualitativo",W16,IF(D16="minimização",Z16/W16,W16/AA16)))) -> 0.75 | AE16: =IF(AB16<>"","",IF(X16="",0,IF(C16="qualitativo",X16,IF(D16="minimização",Z16/X16,X16/AA16)))) -> 0.75 | AF16: =IF(AB16<>"","",IF(MAX(AC16:AE16)-MIN(AC16:AE16)<=Parametros!$B$47,"sim","não")) -> sim | AG16: =IF(AB16<>"",AB16,IF(AND(AF16="sim",$B$23="sim"),"non_discriminative","")) | AH16: =IF(AG16="","sim","não") -> sim | AI16: =IF(ISNUMBER(AC16),AC16,0) -> 0.75 | AJ16: =IF(ISNUMBER(AD16),AD16,0) -> 0.75 | AK16: =IF(ISNUMBER(AE16),AE16,0) -> 0.75 | AL16: =IF(AH16="sim",1,0) -> 1 | AM16: =IF(AND(AH16="sim",Y16<3),TRIM(IF(V16="","AWS ","")&IF(W16="","Google ","")&IF(X16="","Azure","")),"")
A17: Proteção de dados e criptografia | B17: Segurança da Informação | C17: qualitativo | D17: absoluta | E17: =Pesos_Indicadores!H17 -> 0.20454545 | F17: FOUND | G17: alto | H17: 2026 | I17: FOUND | J17: alto | K17: 2026 | L17: FOUND | M17: alto | N17: 2026 | O17: =IF(AND(F17="FOUND",ISNUMBER(H17)),H17,"") -> 2026 | P17: =IF(AND(I17="FOUND",ISNUMBER(K17)),K17,"") -> 2026 | Q17: =IF(AND(L17="FOUND",ISNUMBER(N17)),N17,"") -> 2026 | R17: =IF(OR(Parametros!$B$46="",COUNT(O17:Q17)<2),"não",IF(MAX(O17:Q17)-MIN(O17:Q17)>Parametros!$B$46,"sim","não")) -> não | S17: =IF(AND($R17="sim",OR(F17="FOUND",F17="PARTIAL")),"INVALID",IF(F17<>"FOUND",F17,IF($C17="qualitativo",IF(G17="","NOT_FOUND",IF(ISNA(MATCH(G17,Parametros!$A$35:$A$39,0)),"INVALID",IF(ISNUMBER(VLOOKUP(G17,Parametros!$A$35:$B$39,2,FALSE())),"FOUND","NOT_FOUND"))),IF(ISNUMBER(G17),"FOUND","NOT_FOUND")))) -> FOUND | T17: =IF(AND($R17="sim",OR(I17="FOUND",I17="PARTIAL")),"INVALID",IF(I17<>"FOUND",I17,IF($C17="qualitativo",IF(J17="","NOT_FOUND",IF(ISNA(MATCH(J17,Parametros!$A$35:$A$39,0)),"INVALID",IF(ISNUMBER(VLOOKUP(J17,Parametros!$A$35:$B$39,2,FALSE())),"FOUND","NOT_FOUND"))),IF(ISNUMBER(J17),"FOUND","NOT_FOUND")))) -> FOUND | U17: =IF(AND($R17="sim",OR(L17="FOUND",L17="PARTIAL")),"INVALID",IF(L17<>"FOUND",L17,IF($C17="qualitativo",IF(M17="","NOT_FOUND",IF(ISNA(MATCH(M17,Parametros!$A$35:$A$39,0)),"INVALID",IF(ISNUMBER(VLOOKUP(M17,Parametros!$A$35:$B$39,2,FALSE())),"FOUND","NOT_FOUND"))),IF(ISNUMBER(M17),"FOUND","NOT_FOUND")))) -> FOUND | V17: =IF(S17<>"FOUND","",IF($C17="qualitativo",VLOOKUP(G17,Parametros!$A$35:$B$39,2,FALSE()),G17)) -> 0.75 | W17: =IF(T17<>"FOUND","",IF($C17="qualitativo",VLOOKUP(J17,Parametros!$A$35:$B$39,2,FALSE()),J17)) -> 0.75 | X17: =IF(U17<>"FOUND","",IF($C17="qualitativo",VLOOKUP(M17,Parametros!$A$35:$B$39,2,FALSE()),M17)) -> 0.75 | Y17: =COUNT(V17:X17) -> 3 | Z17: =IF(Y17=0,"",MIN(V17:X17)) -> 0.75 | AA17: =IF(Y17=0,"",MAX(V17:X17)) -> 0.75 | AB17: =IF(NOT(ISNUMBER(E17)),"no_weight",IF(Y17=0,IF(AND(S17="INVALID",T17="INVALID",U17="INVALID"),"invalid_for_comparison","no_evidence"),IF(AND(Y17<3,Parametros!$B$50<>"SIM"),"missing_for_some_providers",IF(C17="qualitativo",IF(OR(Z17<0,AA17>1),"invalid_for_comparison",""),IF(D17="benefício",IF(AA17=0,"non_discriminative",IF(AA17<0,"invalid_for_comparison","")),IF(Z17<=0,"invalid_for_comparison","")))))) | AC17: =IF(AB17<>"","",IF(V17="",0,IF(C17="qualitativo",V17,IF(D17="minimização",Z17/V17,V17/AA17)))) -> 0.75 | AD17: =IF(AB17<>"","",IF(W17="",0,IF(C17="qualitativo",W17,IF(D17="minimização",Z17/W17,W17/AA17)))) -> 0.75 | AE17: =IF(AB17<>"","",IF(X17="",0,IF(C17="qualitativo",X17,IF(D17="minimização",Z17/X17,X17/AA17)))) -> 0.75 | AF17: =IF(AB17<>"","",IF(MAX(AC17:AE17)-MIN(AC17:AE17)<=Parametros!$B$47,"sim","não")) -> sim | AG17: =IF(AB17<>"",AB17,IF(AND(AF17="sim",$B$23="sim"),"non_discriminative","")) | AH17: =IF(AG17="","sim","não") -> sim | AI17: =IF(ISNUMBER(AC17),AC17,0) -> 0.75 | AJ17: =IF(ISNUMBER(AD17),AD17,0) -> 0.75 | AK17: =IF(ISNUMBER(AE17),AE17,0) -> 0.75 | AL17: =IF(AH17="sim",1,0) -> 1 | AM17: =IF(AND(AH17="sim",Y17<3),TRIM(IF(V17="","AWS ","")&IF(W17="","Google ","")&IF(X17="","Azure","")),"")
A18: Valor ou categoria: número publicado (quantitativo) ou nível da rubrica (qualitativo). Ano: ano da fonte (source_year). Status é o da extração, já com a checagem de unidade.
A20: 3.1 Conjunto comparável V (§11)
A21: Indicadores normalizáveis (antes da regra de não discriminação) | B21: =COUNTIF($AF$5:$AF$17,"sim")+COUNTIF($AF$5:$AF$17,"não") -> 12
A22: Deles, os que dão a mesma nota a todos os provedores | B22: =COUNTIF($AF$5:$AF$17,"sim") -> 7
A23: Regra de não discriminação aplicada? | B23: =IF(AND(Parametros!$B$45="SIM",B22<B21),"sim","não") -> não | C23: Não se aplica se nenhum indicador separar os provedores (o conjunto ficaria vazio).
A24: Indicadores no conjunto V (entram na Equação 5) | B24: =COUNTIF($AH$5:$AH$17,"sim") -> 12
A25: Indicadores excluídos | B25: =COUNTIF($AH$5:$AH$17,"não") -> 1
A26: Taxa de comparabilidade | B26: =B24/(B24+B25) -> 0.92307692
A27: Indicadores com zero imputado (penalidade por ausência) | B27: =COUNTIF($AM$5:$AM$17,"?*") -> 1
A28: Motivos de exclusão
A29: no_weight | B29: Sem peso: relevância 'não sei' ou sem resposta.
A30: no_evidence | B30: Nenhum provedor com valor utilizável (e nem todos INVALID).
A31: missing_for_some_providers | B31: Valor para parte dos provedores. Só ocorre com a regra do zero desligada (Parametros B50 = NÃO); ligada, o ausente recebe r = 0.
A32: invalid_for_comparison | B32: Todos INVALID (unidade ou safra divergente) ou fórmula indefinida entre os valores observados.
A33: non_discriminative | B33: Mesma nota para todos: não muda a ordem, só comprime a margem. A nota continua no relatório.

Sheet Pesos_Efetivos
A1: Etapa 4 — Renormalização sobre o conjunto V (§11.2)
A2: w'_j = w_j ÷ Σ_{k∈V} w_k · o mesmo V vale para todos os provedores.
A4: Indicador | B4: Dimensão | C4: Peso global w_j | D4: Entra na Eq. 5? | E4: Peso efetivo w'_j
A5: =Pesos_Indicadores!A5 -> Eficiência energética dos data centers (PUE) | B5: =Pesos_Indicadores!B5 -> Sustentabilidade | C5: =Pesos_Indicadores!H5 -> 0.017045455 | D5: =Normalizacao!AH5 -> sim | E5: =IF(AND(D5="sim",ISNUMBER(C5),$C$19>0),C5/$C$19,"") -> 0.017410714
A6: =Pesos_Indicadores!A6 -> Utilização de fontes de energia renovável (%) | B6: =Pesos_Indicadores!B6 -> Sustentabilidade | C6: =Pesos_Indicadores!H6 -> 0.022727273 | D6: =Normalizacao!AH6 -> sim | E6: =IF(AND(D6="sim",ISNUMBER(C6),$C$19>0),C6/$C$19,"") -> 0.023214286
A7: =Pesos_Indicadores!A7 -> Redução de emissões de gases de efeito estufa | B7: =Pesos_Indicadores!B7 -> Sustentabilidade | C7: =Pesos_Indicadores!H7 -> 0.017045455 | D7: =Normalizacao!AH7 -> sim | E7: =IF(AND(D7="sim",ISNUMBER(C7),$C$19>0),C7/$C$19,"") -> 0.017410714
A8: =Pesos_Indicadores!A8 -> Gestão de resíduos eletrônicos (% de desvio de aterro) | B8: =Pesos_Indicadores!B8 -> Sustentabilidade | C8: =Pesos_Indicadores!H8 -> 0.017045455 | D8: =Normalizacao!AH8 -> sim | E8: =IF(AND(D8="sim",ISNUMBER(C8),$C$19>0),C8/$C$19,"") -> 0.017410714
A9: =Pesos_Indicadores!A9 -> Circularidade e ciclo de vida dos equipamentos | B9: =Pesos_Indicadores!B9 -> Sustentabilidade | C9: =Pesos_Indicadores!H9 -> 0.017045455 | D9: =Normalizacao!AH9 -> sim | E9: =IF(AND(D9="sim",ISNUMBER(C9),$C$19>0),C9/$C$19,"") -> 0.017410714
